<?xml version="1.0"?>
<robot name = "my_rb1_robot" xmlns:xacro="http://www.ros.org/wiki/xacro">
    <xacro:property name="halfpi" value="1.57079632679" />

    <joint name="base_joint" type="fixed">
        <parent link="base_link"/>
        <child link="base_footprint"/>
        <origin xyz="0 0 -0.15" rpy="0 0 0"/>
    </joint>

    <link name = "base_footprint"/>

    <link name="base_link">
        <inertial>
            <mass value="25"/>
            
            <inertia ixx="0.578" ixy="0" ixz="0" iyy="0.578" iyz="0" izz="0.78" />
        </inertial>

        <collision>
            
            <geometry>
                <cylinder length="0.3" radius = "0.25"/>
            </geometry>
        </collision>

        <visual>
            
            <geometry>
                <cylinder length="0.3" radius = "0.25"/>
            </geometry>
            <material name="Blue">
                <color rgba="0 0 1 0.7" />
            </material>
        </visual>
    </link>

    <joint name="rwheel_joint" type="continuous">
        <parent link="base_link"/>
        <child link="right_wheel"/>
        <origin  rpy="0 0 0" xyz = "0 -0.2 -0.15"/>
        <axis rpy="0 0 0" xyz = "0 1 0" />
        <limit effort="10000" velocity="1000" />
        <joint_properties damping="1.0" friction="1.0" />
    </joint>

    <link name="right_wheel">
        <inertial>
            <origin xyz="0 0 0" rpy="0 0 0" />
            <mass value="25" />
            <inertia ixx="1.5417" ixy="0" ixz="0" iyy="3.467" iyz="0" izz="4.742" />
        </inertial>

        <collision>
            <origin  rpy="${halfpi} 0 0" xyz="0 0 0"/>
            <geometry>
                <cylinder length="0.03" radius = "0.025"/>
            </geometry>
        </collision>

        <visual>
            <origin  rpy="${halfpi} 0 0" xyz="0 0 0"/>
            <geometry>
                <cylinder length="0.04" radius = "0.025"/>
            </geometry>
            <material name="Red">
                <color rgba="1 0 0 1" />
            </material>
        </visual>
    </link>
   
    <joint name="lwheel_joint" type="continuous">
        <parent link="base_link"/>
        <child link="left_wheel"/>
        <origin  rpy="0 0 0" xyz = "0 0.2 -0.15"/>
        <axis rpy="0 0 0" xyz = "0 1 0" />
        <limit effort="10000" velocity="1000" />
        <joint_properties damping="1.0" friction="1.0" />
    </joint>

    <link name="left_wheel">
        <inertial>
            <origin xyz="0 0 0" rpy="0 0 0" />
            <mass value="25" />
            <inertia ixx="1.5417" ixy="0" ixz="0" iyy="3.467" iyz="0" izz="4.742" />
        </inertial>

        <collision>
            <origin  rpy="${halfpi} 0 0" xyz="0 0 0"/>
            <geometry>
                <cylinder length="0.03" radius = "0.025"/>
            </geometry>
        </collision>

        <visual>
            <origin  rpy="${halfpi} 0 0" xyz="0 0 0"/>
            <geometry>
                <cylinder length="0.03" radius = "0.025"/>
            </geometry>
            <material name="Red">
                <color rgba="1 0 0 1" />
            </material>
        </visual>
    </link>

    <joint name="fcaster_joint" type="fixed">
        <parent link="base_link"/>
        <child link="front_caster"/>
        <origin xyz="0.1 0 -0.15" rpy="0 0 0" />
        <joint_properties  friction="0.0" />
    </joint>

    <link name="front_caster">
        <inertial>
            <mass value="25" />
            <origin xyz="0 0 0" rpy="0 0 0" />
            <inertia ixx="1.5417" ixy="0" ixz="0" iyy="3.467" iyz="0" izz="4.742" />
        </inertial>

        <collision>
            <geometry>
                <sphere radius="0.025"/>
            </geometry>
        </collision>

        <visual>
            <geometry>
                <sphere radius="0.025"/>
            </geometry>
            <material name="Black">
                <color rgba="1 1 1 1" />
            </material>
        </visual>
    </link>

<joint name="bcaster_joint" type="fixed">
        <parent link="base_link"/>
        <child link="back_caster"/>
        <origin xyz="-0.1 0 -0.15" rpy="0 0 0" />
        <joint_properties  friction="0.0" />
    </joint>

    <link name="back_caster">
        <inertial>
            <mass value="25" />
            <origin xyz="0 0 0" rpy="0 0 0" />
            <inertia ixx="1.5417" ixy="0" ixz="0" iyy="3.467" iyz="0" izz="4.742" />
        </inertial>

        <collision>
            <geometry>
                <sphere radius="0.025"/>
            </geometry>
        </collision>

        <visual>
            <geometry>
                <sphere radius="0.025"/>
            </geometry>
            <material name="Black">
                <color rgba="1 1 1 1" />
            </material>
        </visual>
    </link>

    <joint name="laser_joint" type="fixed">
        <parent link="base_link"/>
        <child link="front_laser"/>
        <origin xyz="0.25 0.0 0.075" rpy="${halfpi*2} 0 0" />
    </joint>

    <link name="front_laser">
        <origin xyz="0 0 0" rpy="0 0 0" />
    </link>
</robot>